Exception in thread Thread-11:
Traceback (most recent call last):
  File "/opt/conda/lib/python3.8/threading.py", line 932, in _bootstrap_inner
    self.run()
  File "/home/ics-home/121/crawler/worker.py", line 26, in run
    scraped_urls = scraper(tbd_url, resp)
  File "/home/ics-home/121/scraper.py", line 7, in scraper
    links = extract_next_links(url, resp)
  File "/home/ics-home/121/scraper.py", line 23, in extract_next_links
    page = urlopen(url)
  File "/opt/conda/lib/python3.8/urllib/request.py", line 222, in urlopen
    return opener.open(url, data, timeout)
  File "/opt/conda/lib/python3.8/urllib/request.py", line 531, in open
    response = meth(req, response)
  File "/opt/conda/lib/python3.8/urllib/request.py", line 640, in http_response
    response = self.parent.error(
  File "/opt/conda/lib/python3.8/urllib/request.py", line 563, in error
    result = self._call_chain(*args)
  File "/opt/conda/lib/python3.8/urllib/request.py", line 502, in _call_chain
    result = func(*args)
  File "/opt/conda/lib/python3.8/urllib/request.py", line 755, in http_error_302
    return self.parent.open(new, timeout=req.timeout)
  File "/opt/conda/lib/python3.8/urllib/request.py", line 531, in open
    response = meth(req, response)
  File "/opt/conda/lib/python3.8/urllib/request.py", line 640, in http_response
    response = self.parent.error(
  File "/opt/conda/lib/python3.8/urllib/request.py", line 569, in error
    return self._call_chain(*args)
  File "/opt/conda/lib/python3.8/urllib/request.py", line 502, in _call_chain
    result = func(*args)
  File "/opt/conda/lib/python3.8/urllib/request.py", line 649, in http_error_default
    raise HTTPError(req.full_url, code, msg, hdrs, fp)
urllib.error.HTTPError: HTTP Error 404: Not Found