OOPs


2021-01-28 17:23:40,029 - Worker-0 - INFO - Downloaded https://password.ics.uci.edu, status <200>, using cache ('styx.ics.uci.edu', 9009).
Exception in thread Thread-1:
Traceback (most recent call last):
  File "/usr/lib64/python3.6/threading.py", line 916, in _bootstrap_inner
    self.run()
  File "/home/cjcontre/121/crawler/worker.py", line 26, in run
    scraped_urls = scraper(tbd_url, resp)
  File "/home/cjcontre/121/scraper.py", line 7, in scraper
    links = extract_next_links(url, resp)
  File "/home/cjcontre/121/scraper.py", line 29, in extract_next_links
    page = urlopen(url)
  File "/usr/lib64/python3.6/urllib/request.py", line 223, in urlopen
    return opener.open(url, data, timeout)
  File "/usr/lib64/python3.6/urllib/request.py", line 532, in open
    response = meth(req, response)
  File "/usr/lib64/python3.6/urllib/request.py", line 642, in http_response
    'http', request, response, code, msg, hdrs)
  File "/usr/lib64/python3.6/urllib/request.py", line 564, in error
    result = self._call_chain(*args)
  File "/usr/lib64/python3.6/urllib/request.py", line 504, in _call_chain
    result = func(*args)
  File "/usr/lib64/python3.6/urllib/request.py", line 756, in http_error_302
    return self.parent.open(new, timeout=req.timeout)
  File "/usr/lib64/python3.6/urllib/request.py", line 532, in open
    response = meth(req, response)
  File "/usr/lib64/python3.6/urllib/request.py", line 642, in http_response
    'http', request, response, code, msg, hdrs)
  File "/usr/lib64/python3.6/urllib/request.py", line 564, in error
    result = self._call_chain(*args)
  File "/usr/lib64/python3.6/urllib/request.py", line 504, in _call_chain
    result = func(*args)
  File "/usr/lib64/python3.6/urllib/request.py", line 756, in http_error_302
    return self.parent.open(new, timeout=req.timeout)
  File "/usr/lib64/python3.6/urllib/request.py", line 532, in open
    response = meth(req, response)
  File "/usr/lib64/python3.6/urllib/request.py", line 642, in http_response
    'http', request, response, code, msg, hdrs)
  File "/usr/lib64/python3.6/urllib/request.py", line 570, in error
    return self._call_chain(*args)
  File "/usr/lib64/python3.6/urllib/request.py", line 504, in _call_chain
    result = func(*args)
  File "/usr/lib64/python3.6/urllib/request.py", line 650, in http_error_default
    raise HTTPError(req.full_url, code, msg, hdrs, fp)
urllib.error.HTTPError: HTTP Error 308: Permanent Redirect